2022-01-23 15:25:53,314 ERROR: Exception on /register [POST] [in /Users/yangzi33/anaconda3/envs/flask_env/lib/python3.9/site-packages/flask/app.py:1454]
Traceback (most recent call last):
  File "/Users/yangzi33/anaconda3/envs/flask_env/lib/python3.9/site-packages/sqlalchemy/engine/base.py", line 3211, in _wrap_pool_connect
    return fn()
  File "/Users/yangzi33/anaconda3/envs/flask_env/lib/python3.9/site-packages/sqlalchemy/pool/base.py", line 307, in connect
    return _ConnectionFairy._checkout(self)
  File "/Users/yangzi33/anaconda3/envs/flask_env/lib/python3.9/site-packages/sqlalchemy/pool/base.py", line 767, in _checkout
    fairy = _ConnectionRecord.checkout(pool)
  File "/Users/yangzi33/anaconda3/envs/flask_env/lib/python3.9/site-packages/sqlalchemy/pool/base.py", line 425, in checkout
    rec = pool._do_get()
  File "/Users/yangzi33/anaconda3/envs/flask_env/lib/python3.9/site-packages/sqlalchemy/pool/impl.py", line 256, in _do_get
    return self._create_connection()
  File "/Users/yangzi33/anaconda3/envs/flask_env/lib/python3.9/site-packages/sqlalchemy/pool/base.py", line 253, in _create_connection
    return _ConnectionRecord(self)
  File "/Users/yangzi33/anaconda3/envs/flask_env/lib/python3.9/site-packages/sqlalchemy/pool/base.py", line 368, in __init__
    self.__connect()
  File "/Users/yangzi33/anaconda3/envs/flask_env/lib/python3.9/site-packages/sqlalchemy/pool/base.py", line 611, in __connect
    pool.logger.debug("Error on connect(): %s", e)
  File "/Users/yangzi33/anaconda3/envs/flask_env/lib/python3.9/site-packages/sqlalchemy/util/langhelpers.py", line 70, in __exit__
    compat.raise_(
  File "/Users/yangzi33/anaconda3/envs/flask_env/lib/python3.9/site-packages/sqlalchemy/util/compat.py", line 207, in raise_
    raise exception
  File "/Users/yangzi33/anaconda3/envs/flask_env/lib/python3.9/site-packages/sqlalchemy/pool/base.py", line 605, in __connect
    connection = pool._invoke_creator(self)
  File "/Users/yangzi33/anaconda3/envs/flask_env/lib/python3.9/site-packages/sqlalchemy/engine/create.py", line 578, in connect
    return dialect.connect(*cargs, **cparams)
  File "/Users/yangzi33/anaconda3/envs/flask_env/lib/python3.9/site-packages/sqlalchemy/engine/default.py", line 584, in connect
    return self.dbapi.connect(*cargs, **cparams)
sqlite3.OperationalError: unable to open database file

The above exception was the direct cause of the following exception:

Traceback (most recent call last):
  File "/Users/yangzi33/anaconda3/envs/flask_env/lib/python3.9/site-packages/flask/app.py", line 2070, in wsgi_app
    response = self.full_dispatch_request()
  File "/Users/yangzi33/anaconda3/envs/flask_env/lib/python3.9/site-packages/flask/app.py", line 1515, in full_dispatch_request
    rv = self.handle_user_exception(e)
  File "/Users/yangzi33/anaconda3/envs/flask_env/lib/python3.9/site-packages/flask/app.py", line 1513, in full_dispatch_request
    rv = self.dispatch_request()
  File "/Users/yangzi33/anaconda3/envs/flask_env/lib/python3.9/site-packages/flask/app.py", line 1499, in dispatch_request
    return self.ensure_sync(self.view_functions[rule.endpoint])(**req.view_args)
  File "/Users/yangzi33/github/microblog/app/routes.py", line 83, in register
    if form.validate_on_submit():
  File "/Users/yangzi33/anaconda3/envs/flask_env/lib/python3.9/site-packages/flask_wtf/form.py", line 100, in validate_on_submit
    return self.is_submitted() and self.validate()
  File "/Users/yangzi33/anaconda3/envs/flask_env/lib/python3.9/site-packages/wtforms/form.py", line 318, in validate
    return super(Form, self).validate(extra)
  File "/Users/yangzi33/anaconda3/envs/flask_env/lib/python3.9/site-packages/wtforms/form.py", line 150, in validate
    if not field.validate(self, extra):
  File "/Users/yangzi33/anaconda3/envs/flask_env/lib/python3.9/site-packages/wtforms/fields/core.py", line 226, in validate
    stop_validation = self._run_validation_chain(form, chain)
  File "/Users/yangzi33/anaconda3/envs/flask_env/lib/python3.9/site-packages/wtforms/fields/core.py", line 246, in _run_validation_chain
    validator(form, self)
  File "/Users/yangzi33/github/microblog/app/forms.py", line 24, in validate_username
    user = User.query.filter_by(username=username.data).first()
  File "/Users/yangzi33/anaconda3/envs/flask_env/lib/python3.9/site-packages/sqlalchemy/orm/query.py", line 2750, in first
    return self.limit(1)._iter().first()
  File "/Users/yangzi33/anaconda3/envs/flask_env/lib/python3.9/site-packages/sqlalchemy/orm/query.py", line 2834, in _iter
    result = self.session.execute(
  File "/Users/yangzi33/anaconda3/envs/flask_env/lib/python3.9/site-packages/sqlalchemy/orm/session.py", line 1688, in execute
    conn = self._connection_for_bind(bind)
  File "/Users/yangzi33/anaconda3/envs/flask_env/lib/python3.9/site-packages/sqlalchemy/orm/session.py", line 1529, in _connection_for_bind
    return self._transaction._connection_for_bind(
  File "/Users/yangzi33/anaconda3/envs/flask_env/lib/python3.9/site-packages/sqlalchemy/orm/session.py", line 747, in _connection_for_bind
    conn = bind.connect()
  File "/Users/yangzi33/anaconda3/envs/flask_env/lib/python3.9/site-packages/sqlalchemy/engine/base.py", line 3165, in connect
    return self._connection_cls(self, close_with_result=close_with_result)
  File "/Users/yangzi33/anaconda3/envs/flask_env/lib/python3.9/site-packages/sqlalchemy/engine/base.py", line 96, in __init__
    else engine.raw_connection()
  File "/Users/yangzi33/anaconda3/envs/flask_env/lib/python3.9/site-packages/sqlalchemy/engine/base.py", line 3244, in raw_connection
    return self._wrap_pool_connect(self.pool.connect, _connection)
  File "/Users/yangzi33/anaconda3/envs/flask_env/lib/python3.9/site-packages/sqlalchemy/engine/base.py", line 3214, in _wrap_pool_connect
    Connection._handle_dbapi_exception_noconnection(
  File "/Users/yangzi33/anaconda3/envs/flask_env/lib/python3.9/site-packages/sqlalchemy/engine/base.py", line 2068, in _handle_dbapi_exception_noconnection
    util.raise_(
  File "/Users/yangzi33/anaconda3/envs/flask_env/lib/python3.9/site-packages/sqlalchemy/util/compat.py", line 207, in raise_
    raise exception
  File "/Users/yangzi33/anaconda3/envs/flask_env/lib/python3.9/site-packages/sqlalchemy/engine/base.py", line 3211, in _wrap_pool_connect
    return fn()
  File "/Users/yangzi33/anaconda3/envs/flask_env/lib/python3.9/site-packages/sqlalchemy/pool/base.py", line 307, in connect
    return _ConnectionFairy._checkout(self)
  File "/Users/yangzi33/anaconda3/envs/flask_env/lib/python3.9/site-packages/sqlalchemy/pool/base.py", line 767, in _checkout
    fairy = _ConnectionRecord.checkout(pool)
  File "/Users/yangzi33/anaconda3/envs/flask_env/lib/python3.9/site-packages/sqlalchemy/pool/base.py", line 425, in checkout
    rec = pool._do_get()
  File "/Users/yangzi33/anaconda3/envs/flask_env/lib/python3.9/site-packages/sqlalchemy/pool/impl.py", line 256, in _do_get
    return self._create_connection()
  File "/Users/yangzi33/anaconda3/envs/flask_env/lib/python3.9/site-packages/sqlalchemy/pool/base.py", line 253, in _create_connection
    return _ConnectionRecord(self)
  File "/Users/yangzi33/anaconda3/envs/flask_env/lib/python3.9/site-packages/sqlalchemy/pool/base.py", line 368, in __init__
    self.__connect()
  File "/Users/yangzi33/anaconda3/envs/flask_env/lib/python3.9/site-packages/sqlalchemy/pool/base.py", line 611, in __connect
    pool.logger.debug("Error on connect(): %s", e)
  File "/Users/yangzi33/anaconda3/envs/flask_env/lib/python3.9/site-packages/sqlalchemy/util/langhelpers.py", line 70, in __exit__
    compat.raise_(
  File "/Users/yangzi33/anaconda3/envs/flask_env/lib/python3.9/site-packages/sqlalchemy/util/compat.py", line 207, in raise_
    raise exception
  File "/Users/yangzi33/anaconda3/envs/flask_env/lib/python3.9/site-packages/sqlalchemy/pool/base.py", line 605, in __connect
    connection = pool._invoke_creator(self)
  File "/Users/yangzi33/anaconda3/envs/flask_env/lib/python3.9/site-packages/sqlalchemy/engine/create.py", line 578, in connect
    return dialect.connect(*cargs, **cparams)
  File "/Users/yangzi33/anaconda3/envs/flask_env/lib/python3.9/site-packages/sqlalchemy/engine/default.py", line 584, in connect
    return self.dbapi.connect(*cargs, **cparams)
sqlalchemy.exc.OperationalError: (sqlite3.OperationalError) unable to open database file
(Background on this error at: http://sqlalche.me/e/14/e3q8)
